2023-12-04 02:41:28,589 ERROR log 53483 123145567502336 Internal Server Error: /graphql
Traceback (most recent call last):
  File "/Library/Frameworks/Python.framework/Versions/3.11/lib/python3.11/site-packages/graphene_django/settings.py", line 80, in import_from_string
    module = importlib.import_module(module_path)
             ^^^^^^^^^^^^^^^^^^^^^^^^^^^^^^^^^^^^
  File "/Library/Frameworks/Python.framework/Versions/3.11/lib/python3.11/importlib/__init__.py", line 126, in import_module
    return _bootstrap._gcd_import(name[level:], package, level)
           ^^^^^^^^^^^^^^^^^^^^^^^^^^^^^^^^^^^^^^^^^^^^^^^^^^^^
  File "<frozen importlib._bootstrap>", line 1204, in _gcd_import
  File "<frozen importlib._bootstrap>", line 1176, in _find_and_load
  File "<frozen importlib._bootstrap>", line 1126, in _find_and_load_unlocked
  File "<frozen importlib._bootstrap>", line 241, in _call_with_frames_removed
  File "<frozen importlib._bootstrap>", line 1204, in _gcd_import
  File "<frozen importlib._bootstrap>", line 1176, in _find_and_load
  File "<frozen importlib._bootstrap>", line 1147, in _find_and_load_unlocked
  File "<frozen importlib._bootstrap>", line 690, in _load_unlocked
  File "<frozen importlib._bootstrap_external>", line 940, in exec_module
  File "<frozen importlib._bootstrap>", line 241, in _call_with_frames_removed
  File "/Library/Frameworks/Python.framework/Versions/3.11/lib/python3.11/site-packages/graphql_jwt/__init__.py", line 1, in <module>
    from . import relay
  File "/Library/Frameworks/Python.framework/Versions/3.11/lib/python3.11/site-packages/graphql_jwt/relay.py", line 5, in <module>
    from . import mixins
  File "/Library/Frameworks/Python.framework/Versions/3.11/lib/python3.11/site-packages/graphql_jwt/mixins.py", line 1, in <module>
    from django.utils.translation import ugettext as _
ImportError: cannot import name 'ugettext' from 'django.utils.translation' (/Library/Frameworks/Python.framework/Versions/3.11/lib/python3.11/site-packages/django/utils/translation/__init__.py)

During handling of the above exception, another exception occurred:

Traceback (most recent call last):
  File "/Library/Frameworks/Python.framework/Versions/3.11/lib/python3.11/site-packages/asgiref/sync.py", line 486, in thread_handler
    raise exc_info[1]
  File "/Library/Frameworks/Python.framework/Versions/3.11/lib/python3.11/site-packages/django/core/handlers/exception.py", line 42, in inner
    response = await get_response(request)
               ^^^^^^^^^^^^^^^^^^^^^^^^^^^
  File "/Library/Frameworks/Python.framework/Versions/3.11/lib/python3.11/site-packages/asgiref/sync.py", line 486, in thread_handler
    raise exc_info[1]
  File "/Library/Frameworks/Python.framework/Versions/3.11/lib/python3.11/site-packages/django/core/handlers/base.py", line 253, in _get_response_async
    response = await wrapped_callback(
               ^^^^^^^^^^^^^^^^^^^^^^^
  File "/Library/Frameworks/Python.framework/Versions/3.11/lib/python3.11/site-packages/asgiref/sync.py", line 448, in __call__
    ret = await asyncio.wait_for(future, timeout=None)
          ^^^^^^^^^^^^^^^^^^^^^^^^^^^^^^^^^^^^^^^^^^^^
  File "/Library/Frameworks/Python.framework/Versions/3.11/lib/python3.11/asyncio/tasks.py", line 452, in wait_for
    return await fut
           ^^^^^^^^^
  File "/Library/Frameworks/Python.framework/Versions/3.11/lib/python3.11/site-packages/asgiref/current_thread_executor.py", line 22, in run
    result = self.fn(*self.args, **self.kwargs)
             ^^^^^^^^^^^^^^^^^^^^^^^^^^^^^^^^^^
  File "/Library/Frameworks/Python.framework/Versions/3.11/lib/python3.11/site-packages/asgiref/sync.py", line 490, in thread_handler
    return func(*args, **kwargs)
           ^^^^^^^^^^^^^^^^^^^^^
  File "/Library/Frameworks/Python.framework/Versions/3.11/lib/python3.11/site-packages/django/views/decorators/csrf.py", line 54, in wrapped_view
    return view_func(*args, **kwargs)
           ^^^^^^^^^^^^^^^^^^^^^^^^^^
  File "/Library/Frameworks/Python.framework/Versions/3.11/lib/python3.11/site-packages/django/views/generic/base.py", line 96, in view
    self = cls(**initkwargs)
           ^^^^^^^^^^^^^^^^^
  File "/Library/Frameworks/Python.framework/Versions/3.11/lib/python3.11/site-packages/graphene_django/views.py", line 110, in __init__
    middleware = graphene_settings.MIDDLEWARE
                 ^^^^^^^^^^^^^^^^^^^^^^^^^^^^
  File "/Library/Frameworks/Python.framework/Versions/3.11/lib/python3.11/site-packages/graphene_django/settings.py", line 127, in __getattr__
    val = perform_import(val, attr)
          ^^^^^^^^^^^^^^^^^^^^^^^^^
  File "/Library/Frameworks/Python.framework/Versions/3.11/lib/python3.11/site-packages/graphene_django/settings.py", line 68, in perform_import
    return [import_from_string(item, setting_name) for item in val]
           ^^^^^^^^^^^^^^^^^^^^^^^^^^^^^^^^^^^^^^^^^^^^^^^^^^^^^^^^
  File "/Library/Frameworks/Python.framework/Versions/3.11/lib/python3.11/site-packages/graphene_django/settings.py", line 68, in <listcomp>
    return [import_from_string(item, setting_name) for item in val]
            ^^^^^^^^^^^^^^^^^^^^^^^^^^^^^^^^^^^^^^
  File "/Library/Frameworks/Python.framework/Versions/3.11/lib/python3.11/site-packages/graphene_django/settings.py", line 89, in import_from_string
    raise ImportError(msg)
ImportError: Could not import 'graphql_jwt.middleware.JSONWebTokenMiddleware' for Graphene setting 'MIDDLEWARE'. ImportError: cannot import name 'ugettext' from 'django.utils.translation' (/Library/Frameworks/Python.framework/Versions/3.11/lib/python3.11/site-packages/django/utils/translation/__init__.py).
2023-12-04 02:41:28,793 ERROR runserver 53483 123145517133824 [35;1mHTTP GET /graphql 500 [0.37, 127.0.0.1:64262][0m
